<mujoco model="reacher">
	<compiler angle="radian" inertiafromgeom="true"/>
	<default>
		<joint armature="1" damping="1" limited="true"/>
		<geom contype="0" friction="1 0.1 0.1" rgba="0.7 0.7 0 1"/>
	</default>
	<option gravity="0 0 -9.81" integrator="RK4" timestep="0.01"/>
	<worldbody>
		<!-- Arena -->
		<geom conaffinity="0" contype="0" name="ground" pos="0 0 0" rgba="0.9 0.9 0.9 1" size="1 1 10" type="plane"/>
		<geom conaffinity="0" fromto="-.3 -.3 .01 .3 -.3 .01" name="sideS" rgba="0 0.5 1 1" size=".02" type="capsule"/>
		<geom conaffinity="0" fromto=" .3 -.3 .01 .3  .3 .01" name="sideE" rgba="0 0.5 1 1" size=".02" type="capsule"/>
		<geom conaffinity="0" fromto="-.3  .3 .01 .3  .3 .01" name="sideN" rgba="0 0.5 1 1" size=".02" type="capsule"/>
		<geom conaffinity="0" fromto="-.3 -.3 .01 -.3 .3 .01" name="sideW" rgba="0 0.5 1 1" size=".02" type="capsule"/>
		<!-- Agent -->
		<body name="agent" pos=".1 -.1 .01">
			<joint axis="1 0 0" limited="true" name="agent_x" pos="0 0 0" range="-.27 .27" ref=".1" type="slide"/>
			<joint axis="0 1 0" limited="true" name="agent_y" pos="0 0 0" range="-.27 .27" ref="-.1" type="slide"/>
			<geom conaffinity="0" contype="0" name="agent_body" pos="0 0 0" rgba="0 0.75 1 1" size="0.02 0.02 .0001" type="box"/>
			<joint axis="0 0 1" limited="false" name="viewer" pos="0 0 0" type="hinge"/>
			<body name="agent_eye" pos="0 0 0">
				<geom name="eye" pos="0.015 0 0.0001" rgba="0 0 0 1" size="0.005 0.009 0.0001" type="box"/>
			</body>
		</body>

		<!-- Target -->
		<body name="target" pos=".1 -.1 .01">
			<joint armature="0" damping="0" stiffness="0" axis="1 0 0" limited="true" name="target_x" pos="0 0 0" range="-.27 .27" ref=".1" type="slide"/>
			<joint armature="0" damping="0" stiffness="0" axis="0 1 0" limited="true" name="target_y" pos="0 0 0" range="-.27 .27" ref="-.1" type="slide"/>
			<geom conaffinity="0" contype="0" name="target_body" pos="0 0 0" rgba="1 0 0 1" size=".01" type="sphere"/>
		</body>
	</worldbody>
	<actuator>
		<motor ctrllimited="true" ctrlrange="-1.0 1.0" gear="100.0" joint="agent_x"/>
		<motor ctrllimited="true" ctrlrange="-1.0 1.0" gear="100.0" joint="agent_y"/>
		<motor ctrllimited="true" ctrlrange="-1.0 1.0" gear="200.0" joint="viewer"/>
	</actuator>
</mujoco>